Workbook
Name __A100000: #REF!
Name __A100000: #REF!
Name __A100000: #REF!
Name __A100002: #REF!
Name __A100002: #REF!
Name __A100002: #REF!
Name __A111119: #REF!
Name __A111119: #REF!
Name __A111119: #REF!
Name __A111192: #REF!
Name __A111192: #REF!
Name __A111192: #REF!
Name __A70000: #REF!
Name __A70000: #REF!
Name __A70000: #REF!
Name __A99999: #REF!
Name __A99999: #REF!
Name __A99999: #REF!
Name __ADM1: #REF!
Name __ADM1: #REF!
Name __ADM1: #REF!
Name __ADM2: #REF!
Name __ADM2: #REF!
Name __ADM2: #REF!
Name __ADM3: #REF!
Name __ADM3: #REF!
Name __ADM3: #REF!
Name __ADM4: #REF!
Name __ADM4: #REF!
Name __ADM4: #REF!
Name __ADM5: #REF!
Name __ADM5: #REF!
Name __ADM5: #REF!
Name __AKZ02: #REF!
Name __AKZ02: #REF!
Name __AKZ02: #REF!
Name __AST90: #REF!
Name __AST90: #REF!
Name __AST90: #REF!
Name __DAT1: #REF!
Name __DAT1: #REF!
Name __DAT1: #REF!
Name __DAT10: #REF!
Name __DAT10: #REF!
Name __DAT10: #REF!
Name __DAT11: #REF!
Name __DAT11: #REF!
Name __DAT11: #REF!
Name __DAT12: #REF!
Name __DAT12: #REF!
Name __DAT12: #REF!
Name __DAT2: #REF!
Name __DAT2: #REF!
Name __DAT2: #REF!
Name __DAT3: #REF!
Name __DAT3: #REF!
Name __DAT3: #REF!
Name __DAT4: #REF!
Name __DAT4: #REF!
Name __DAT4: #REF!

Sheet Device List
A2: No | B2: Network Information | G2: Physical Information | O2: System Information | AB2: Hardware Information | AH2: Software Information | AQ2: Software (Specific) | AW2: Access Permission | AY2: Email Address Logon | AZ2: Updated | BB2: Remark
B3: IP Address | C3: Computer Name | D3: User Name | E3: Workgroup/Domain | F3: Use DHCP | G3: Type | H3: PIC | J3: Department | K3: Location | M3: Year of Purchased | N3: Age (Years) | O3: Brand | P3: Model | Q3: CPU | R3: Speed (GHz) | S3: RAM (MB) | T3: HDD | V3: SSD | X3: Monitor | AB3: Hardware Identification | AD3: Fixed Asset Number | AF3: MAC Address | AH3: Windows | AL3: Office | AO3: Antivirus | AQ3: HRM | AR3: SAP | AS3: Stock | AT3: Garoon | AU3: Team | AV3: Other | AW3: Internet | AX3: Email | AZ3: Date | BA3: By
I4: PIC | T4: HDD(GB) | U4: Hardware Name | V4: SSD(GB) | W4: Hardware Name | X4: Brand | Y4: Model | Z4: Specification | AA4: Serial Number | AB4: Serial Number | AC4: Service Tag | AD4: CPU | AE4: Monitor | AF4: LAN | AG4: Wireless | AH4: Version | AI4: Bit | AJ4: License Type | AK4: License Key | AL4: Version | AM4: License Type | AN4: License Key | AO4: Name | AP4: Version
A5: 1 | B5: 192.168.100.188 | C5: KF-AD-01 | D5: nk1lecture2 | E5: NK-NIPPO | F5: No | G5: PC | H5: AD-IT | I5: Mr. Amnat Kunwandee | J5: AD | K5: NK1 | L5: NK1 Vip1 Room | M5: 2019 | N5: =2026-M5 -> 7 | O5: Dell Inc. | P5: OptiPlex 3070 | Q5: Intel(R) Core(TM) i5-9500 CPU @ 3.00GHz | R5: 3.00GHz | S5: 8192 | T5: 1024 | U5: Intel Optane+932GBHDD | X5: Sony | Y5: KLV-40S400A | Z5: 40 inch, Wide | AA5: 6002190 | AB5: 6TQRB03 | AC5: 6TQRB03 | AD5: NKF-19-006-O 03/24 | AE5: KF2-08-030-O | AF5: E4-54-E8-7D-F5-F2 | AG5: Don't have | AH5: Windows 11 Professional Edition (x64) | AI5: 64 | AJ5: OEM | AK5: PFMNV-Q7B4G-23HT3-Y9PH2-MP2KC | AL5: Microsoft Office Standard 2019 - en-us | AM5: Volume Licensing | AN5: V8TVB | AO5: Cybereason | AP5: 23.2.243.1 | AU5: P | AV5: Zoom | AW5: YES | AX5: NO | AY5: - | AZ5: 45841 | BA5: anucha
A6: 2 | B6: 192.168.123.118 | C6: KF-AD-02 | D6: nk1vip2 | E6: NK-NIPPO | F6: No | G6: PC | H6: AD-IT | I6: Mr. Amnat Kunwandee | J6: AD | K6: NK1 | L6: NK1 Vip2 Room | M6: 2019 | N6: =2026-M6 -> 7 | O6: Dell Inc. | P6: OptiPlex 3070 | Q6: Intel(R) Core(TM) i5-9500 CPU @ 3.00GHz | R6: 3.00GHz | S6: 8192 | V6: 500 | W6: NVMe Samsung SSD 980 | X6: Sony | Y6: KLV-32W550A | Z6: 32 inch, Wide | AA6: 6002255 | AB6: 6TBQB03 | AC6: 6TBQB03 | AD6: NKF-19-006-O 10/24 | AE6: Don't have | AF6: E4-54-E8-7D-F6-91 | AG6: Don't have | AH6: Windows 11 Professional Edition (x64) | AI6: 64 | AJ6: OEM | AK6: 6PV2R-NYXF6-M2CVT-C77MF-QGPKC | AL6: Microsoft Office Standard 2019 - en-us | AM6: Volume Licensing | AN6: V8TVB | AO6: Cybereason | AP6: 23.2.243.1 | AU6: P | AV6: Zoom,Skype | AW6: YES | AX6: YES | AY6: nk1vip2@nip.co.th | AZ6: 45841 | BA6: anucha
A7: 3 | B7: 192.168.100.223 | C7: KF-AD-03 | D7: nk1director | E7: NK-NIPPO | F7: Yes | G7: PC | H7: AD-IT | I7: Mr. Amnat Kunwandee | J7: AD | K7: NK1 | L7: NK1 Vip3 Room | M7: 2023 | N7: =2026-M7 -> 3 | O7: Dell Inc. | P7: OptiPlex 7000 | Q7: 12th Gen Intel(R) Core(TM) i5-12500 | R7: 3.00GHz | S7: 8192 | T7: 1024 | U7: ST1000DM010-2EP102 | V7: 256 | W7: NVMe Micron 2450 NVMe 256GB | X7: Sony | Y7: KLV-32W550A | Z7: 32 inch, Wide | AA7: 6002247 | AB7: 66V77V3 | AC7: 66V77V3 | AD7: ยังไม่ติดสติกเกอร์ | AE7: Don't have | AF7: CC-96-E5-12-8F-92 | AG7: Don't have | AH7: Windows 11 Professional Edition (x64) | AI7: 64 | AJ7: OEM | AK7: NJ3GP-QGKF4-X4BK6-YQFCR-BY6PT | AL7: Microsoft Office Home and Business 2021 - en-us | AM7: Full Package Products | AN7: X2HMD | AO7: Cybereason | AP7: 23.2.243.1 | AU7: P | AV7: Zoom,Skype,Webex | AW7: YES | AX7: YES | AY7: nk1director@nip.co.th | AZ7: 45841 | BA7: anucha
A8: 4 | B8: 192.168.100.193 | C8: KF-AD-04 | D8: nk1guest | E8: NK-NIPPO | F8: No | G8: PC | H8: AD-IT | I8: Mr. Amnat Kunwandee | J8: AD | K8: NK1 | L8: Guest Room | M8: 2023 | N8: =2026-M8 -> 3 | O8: Dell Inc. | P8: OptiPlex 7000 | Q8: 12th Gen Intel(R) Core(TM) i5-12500 | R8: 3.00GHz | S8: 8192 | T8: 1024 | U8: ST1000DM010-2EP102 | V8: 256 | W8: NVMe Micron 2450 NVMe 256GB | X8: Dell | Y8: E1715SC | Z8: 17 inch, Square | AA8: CN-06FDC0-TV100-328-00KU-A17 | AB8: 36V77V3 | AC8: 36V77V3 | AD8: ยังไม่ติดสติกเกอร์ | AE8: Don't have | AF8: CC-96-E5-12-8E-51 | AG8: Don't have | AH8: Windows 11 Professional Edition (x64) | AI8: 64 | AJ8: OEM | AK8: QQXN2-K7CDT-2CPVK-6KG2B-7MJGG | AL8: Microsoft Office Home and Business 2021 - en-us | AM8: Full Package Products | AN8: X2HMD | AO8: Cybereason | AP8: 23.2.243.1 | AU8: P | AV8: Zoom,Skype | AW8: YES | AX8: YES | AY8: nk1guest@nip.co.th | AZ8: 45841 | BA8: anucha
A9: 5 | B9: 192.168.100.127 | C9: KF-AD-05 | D9: nk1conference1 | E9: NK-NIPPO | F9: No | G9: PC | H9: AD-IT | I9: Mr. Amnat Kunwandee | J9: AD | K9: NK1 | L9: Conference Room 1 | M9: 2019 | N9: =2026-M9 -> 7 | O9: Dell Inc. | P9: OptiPlex 3070 | Q9: Intel(R) Core(TM) i5-9500 CPU @ 3.00GHz | R9: 3.00GHz | S9: 8192 | V9: 256 | W9: NVMe TS256GMTE110S | X9: Acer | Y9: X1226AH | Z9: Projector | AA9: 10200064459 | AB9: 6T1NB03 | AC9: 6T1NB03 | AD9: NKF-19-006-O 06/24 | AE9: NKF-21-003-O 03/03 | AF9: E4-54-E8-7E-01-5B | AG9: Don't have | AH9: Windows 11 Professional Edition (x64) | AI9: 64 | AJ9: OEM | AK9: NKCH6-RRMHC-3YW8R-C3XFJ-HMH22 | AL9: Microsoft Office Standard 2019 - en-us | AM9: Volume Licensing | AN9: V8TVB | AO9: Cybereason | AP9: 23.2.243.1 | AU9: P | AV9: Zoom,Skype | AW9: YES | AX9: YES | AY9: nk1conference1@nip.co.th | AZ9: 45841 | BA9: anucha
A10: 6 | B10: 192.168.10.19 | C10: KF-AD-08 | D10: nk1bigsalon | E10: NK-NIPPO | F10: Yes | G10: PC | H10: AD-IT | I10: Mr. Amnat Kunwandee | J10: AD | K10: NK1 | L10: Bigsalon Room | M10: 2019 | N10: =2026-M10 -> 7 | O10: Dell Inc. | P10: OptiPlex 3070 | Q10: Intel(R) Core(TM) i5-9500 CPU @ 3.00GHz | R10: 3.00GHz | S10: 8192 | V10: 256 | W10: NVMe TS256GMTE110S | X10: Dell | Y10: E1715S | Z10: 17 inch, Square | AA10: CN-06FDC0-TV100-31V-052U-A17 | AB10: 6VRQB03 | AC10: 6VRQB03 | AD10: NKF-19-006-O 01/24 | AF10: E4-54-E8-7E-00-AB | AG10: Don't have | AH10: Windows 11 Professional Edition (x64) | AI10: 64 | AJ10: OEM | AK10: 27HVN-WMPDR-RRWTD-X9XR2-BTDGP | AL10: Microsoft Office Standard 2019 - en-us | AM10: Volume Licensing | AN10: V8TVB | AO10: Cybereason | AP10: 23.2.243.1 | AR10: P | AU10: P | AW10: YES | AX10: NO | AY10: - | AZ10: 45841 | BA10: anucha
A11: 7 | B11: 192.168.123.121 | C11: KF-AD-09 | D11: nk1lecture1 | E11: NK-NIPPO | F11: No | G11: PC | H11: AD-IT | I11: Mr. Amnat Kunwandee | J11: AD | K11: NK1 | L11: Lecture Room 1 | M11: 2019 | N11: =2026-M11 -> 7 | O11: Dell Inc. | P11: OptiPlex 3070 | Q11: Intel(R) Core(TM) i5-9500 CPU @ 3.00GHz | R11: 3.00GHz | S11: 8192 | T11: 1024 | U11: Intel Optane+932GBHDD | X11: Dell | Y11: E178FPC | Z11: 17 inch, Square | AA11: Q40G17N-700-11C XY | AB11: 6V8MB03 | AC11: 6V8MB03 | AD11: NKF-19-006-O 14/24 | AE11: KF4-07-016-O 01 | AF11: E4-54-E8-7D-FC-4A | AG11: Don't have | AH11: Windows 11 Professional Edition (x64) | AI11: 64 | AJ11: OEM | AK11: X9WDJ-GXNH6-JYWC6-MT6HY-QJ3GP | AL11: Microsoft Office Standard 2019 - en-us | AM11: Volume Licensing | AN11: KKY9Y | AO11: Cybereason | AP11: 23.2.243.1 | AQ11: P | AR11: P | AU11: P | AV11: Zoom | AW11: YES | AX11: YES | AY11: nk1lecture1@nip.co.th | AZ11: 45841 | BA11: anucha
A12: 8 | B12: 192.168.123.122 | C12: KF-AD-10 | D12: natnicha.s | E12: NK-NIPPO | F12: Yes | G12: PC | H12: AD-IT | I12: Mr. Amnat Kunwandee | J12: AD | K12: NK1 | L12: Lecture Room 2 | M12: 2019 | N12: =2026-M12 -> 7 | O12: Dell Inc. | P12: OptiPlex 3070 | Q12: Intel(R) Core(TM) i5-9500 CPU @ 3.00GHz | R12: 3.00GHz | S12: 8192 | T12: 1024 | U12: ST1000DM010-2EP102 | X12: Dell | Y12: E197FPF | Z12: 19 inch, Square | AA12: CN-0UH570-72872-69T-ODLL | AB12: 6SWRB03 | AC12: 6SWRB03 | AD12: NKF-19-006-O 13/24 | AE12: KF5-09-010-O-01/03 | AF12: E4-54-E8-7D-FB-04 | AG12: Don't have | AH12: Windows 11 Professional Edition (x64) | AI12: 64 | AJ12: OEM | AK12: WNFHF-WC92T-WQ9YV-666HW-GVJXC | AL12: Microsoft Office Standard 2019 - en-us | AM12: Volume Licensing | AN12: KKY9Y | AO12: Cybereason | AP12: 23.2.243.1 | AQ12: P | AR12: P | AU12: P | AW12: YES | AX12: NO | AY12: - | AZ12: 45841 | BA12: anucha
A13: 9 | B13: 192.168.100.216 | C13: KF-AD-11 | D13: nk1meeting1 | E13: NK-NIPPO | F13: Yes | G13: PC | H13: AD-IT | I13: Mr. Amnat Kunwandee | J13: AD | K13: NK1 | L13: Meeting Room 1 (Offoce Center) | M13: 2019 | N13: =2026-M13 -> 7 | O13: Dell Inc. | P13: OptiPlex 3070 | Q13: Intel(R) Core(TM) i5-9500 CPU @ 3.00GHz | R13: 3.40GHz | S13: 8192 | V13: 500 | W13: Samsung SSD 980 500GB | X13: Sony | Y13: KLV-32V300A | Z13: 32 inch, Wide | AA13: 6004791 | AB13: 6T1MB03 | AC13: 6T1MB03 | AD13: NKF-19-006-O 13/24 | AE13: Don't have | AF13: E4-54-E8-7D-FA-89 | AG13: Don't have | AH13: Windows 11 Professional Edition (x64) | AI13: 64 | AJ13: OEM | AK13: YTN2P-RJ2D2-MYRHX-2VFMG-C9XTP | AL13: Microsoft Office Standard 2019 - en-us | AM13: Volume Licensing | AN13: V8TVB | AO13: Cybereason | AP13: 23.2.243.1 | AR13: P | AU13: P | AV13: Skype | AW13: YES | AX13: YES | AY13: nk1floor1conference@nip.co.th | AZ13: 45841 | BA13: anucha
A14: 10 | B14: 192.168.20.124 | C14: KF-AD-12 | D14: nk1meeting2 | E14: NK-NIPPO | F14: Yes | G14: PC | H14: AD-IT | I14: Mr. Amnat Kunwandee | J14: AD | K14: NK1 | L14: Meeting Room 2 (Offoce Center) | M14: 2019 | N14: =2026-M14 -> 7 | O14: Dell Inc. | P14: OptiPlex 3070 | Q14: Intel(R) Core(TM) i5-9500 CPU @ 3.00GHz | R14: 3.00GHz | S14: 8192 | V14: 500 | W14: NVMe Samsung SSD 980 | X14: Sony | Y14: KLV-32W550A | Z14: 32 inch, Wide | AA14: 6002248 | AB14: 6SSRB03 | AC14: 6SSRB03 | AD14: KF4-19-002-O 11/11 | AE14: Don't have | AF14: E4-54-E8-7D-FA-9A | AG14: Don't have | AH14: Windows 11 Professional Edition (x64) | AI14: 64 | AJ14: OEM | AK14: P9H88-KDNPJ-QTV2W-C2MQ2-Q3WXC | AL14: Microsoft Office Standard 2019 - en-us | AM14: Volume Licensing | AN14: V8TVB | AO14: Cybereason | AP14: 23.2.243.1 | AR14: P | AU14: P | AV14: Skype | AW14: YES | AX14: NO | AY14: - | AZ14: 45841 | BA14: anucha
A15: 11 | B15: 192.168.200.195 | C15: KF-AD-13 | D15: nk2vip1 | E15: NK-NIPPO | F15: No | G15: PC | H15: AD-IT | I15: Mr. Amnat Kunwandee | J15: AD | K15: NK2 | L15: NK2 Vip1 Room | M15: 2019 | N15: =2026-M15 -> 7 | O15: Dell Inc. | P15: OptiPlex 3070 | Q15: Intel(R) Core(TM) i5-9500 CPU @ 3.00GHz | R15: 3.00GHz | S15: 8192 | V15: 500 | W15: Samsung SSD 980 500GB | X15: acer | Y15: X1226AH | Z15: Projector | AA15: MRJR11006102003415910 | AB15: 6T5QB03 | AC15: 6T5QB03 | AD15: NKF-19-006-O 20/24 | AE15: NKF-21-003-0-02/03 | AF15: E4-54-E8-7E-00-19 | AG15: Don't have | AH15: Windows 11 Professional Edition (x64) | AI15: 64 | AJ15: OEM | AK15: W8GRJ-PNGKB-J7BXH-2HFFC-RVV22 | AL15: Microsoft Office Standard 2019 - en-us | AM15: Volume Licensing | AN15: KKY9Y | AO15: Cybereason | AP15: 23.2.243.1 | AR15: P | AU15: P | AV15: Zoom | AW15: YES | AX15: YES | AY15: nk2vip1@nip.co.th | AZ15: 45841 | BA15: anucha
A16: 12 | B16: 192.168.200.101 | C16: KF-AD-14 | D16: nk2vip2 | E16: NK-NIPPO | F16: No | G16: PC | H16: AD-IT | I16: Mr. Amnat Kunwandee | J16: AD | K16: NK2 | L16: NK2 Vip2 Room | M16: 2019 | N16: =2026-M16 -> 7 | O16: Dell Inc. | P16: OptiPlex 3070 | Q16: Intel(R) Core(TM) i5-9500 CPU @ 3.00GHz | R16: 3.00GHz | S16: 8192 | V16: 256 | W16: NVMe Samsung SSD 970 | X16: Acer | Y16: DNX1522 | Z16: Projector | AA16: MRJP311006728012975900 | AB16: 6T2KB03 | AC16: 6T2KB03 | AD16: NKF-19-006-O 21/24 | AE16: NKF-17-001-O | AF16: E4-54-E8-7E-01-18 | AG16: Don't have | AH16: Windows 11 Professional Edition (x64) | AI16: 64 | AJ16: OEM | AK16: P2WNR-CCYBB-CMR6C-WF7QG-J2QGP | AL16: Microsoft Office Standard 2019 - en-us | AM16: Volume Licensing | AN16: V8TVB | AO16: Cybereason | AP16: 23.2.243.1 | AR16: P | AU16: P | AV16: Zoom | AW16: YES | AX16: YES | AY16: nk2vip2@nip.co.th | AZ16: 45841 | BA16: anucha
A17: 13 | B17: 192.168.123.113 | C17: KF-AD-18 | D17: anurak.s | E17: NK-NIPPO | F17: Yes | G17: NB | H17: Anurak Sareekaew | I17: Mr. Anurak Sareekaew | J17: AD | K17: NK1 | L17: Office Ad | M17: 2022 | N17: =2026-M17 -> 4 | O17: Dell Inc. | P17: Latitude 7320 | Q17: 11th Gen Intel(R) Core(TM) i5-1135G7 @ 2.40GHz | R17: 2.40GHz | S17: 16384 | V17: 500 | W17: NVMe KBG40ZNS512G NVMe KIOXIA 512GB | X17: Dell | Y17: E170Sc | Z17: 17 inch, Square | AA17: CN-0M875N-64180-08P-3VKM | AB17: 9XS43M3 | AC17: 9XS43M3 | AD17: NKF-22-001-O | AE17: NKF-11-001-O | AF17: D4-54-8B-64-20-6D | AG17: D4-54-8B-64-20-6C | AH17: Windows 11 Professional Edition (x64) | AI17: 64 | AJ17: OEM | AK17: 66N4J-J8Q3C-2TVR4-W3Q77-KHKCT | AL17: Microsoft Office LTSC Standard 2021 - en-us | AM17: Volume Licensing | AN17: 8MCC7 | AO17: Cybereason | AP17: 23.2.243.1 | AT17: P | AW17: YES | AX17: YES | AY17: sanurak@nip.co.th | AZ17: 45841 | BA17: anucha
A18: 14 | B18: 192.168.104.25 | C18: KF-AD-19 | D18: yajai.s | E18: NK-NIPPO | F18: No | G18: PC | H18: Yajai Samanpong | I18: Ms. Yajai Samanpong | J18: AD - HRM | K18: NK1 | L18: Office Ad | M18: 2019 | N18: =2026-M18 -> 7 | O18: Dell Inc. | P18: OptiPlex 3070 | Q18: Intel(R) Core(TM) i5-9500 CPU @ 3.00GHz | R18: 3.00GHz | S18: 8192 | T18: 1024 | U18: Intel Optane+932GBHDD | X18: Lenovo | Y18: ThinkVision | Z18: 17 inch, Square | AA18: VNAXLX9 | AB18: 6TDLB03 | AC18: 6TDLB03 | AD18: NKF-19-006-O 02/24 | AE18: NKF-10-063-O | AF18: E4-54-E8-7D-7D-A9 | AG18: Don't have | AH18: Windows 11 Professional Edition (x64) | AI18: 64 | AJ18: OEM | AK18: N7WMF-QW8K6-8978H-KXKJF-W8F9C | AL18: Microsoft Office Standard 2019 - en-us | AM18: Volume Licensing | AN18: KKY9Y | AO18: Cybereason | AP18: 23.2.243.1 | AQ18: P | AR18: P | AT18: P | AW18: YES | AX18: YES | AY18: syajai@nip.co.th | AZ18: 45841 | BA18: anucha
A19: 15 | B19: 192.168.104.26 | C19: KF-AD-20 | D19: supawadee.w | E19: NK-NIPPO | F19: No | G19: PC | H19: Supawadee Wilapan | I19: Ms. Supawadee Wilapan | J19: AD - HRM | K19: NK1 | L19: Office Ad | M19: 2019 | N19: =2026-M19 -> 7 | O19: Dell Inc. | P19: OptiPlex 3070 | Q19: Intel(R) Core(TM) i5-9500 CPU @ 3.00GHz | R19: 3.40GHz | S19: 8192 | T19: 1024 | U19: ST1000DM010-2EP102 | V19: 500 | W19: Samsung SSD 980 500GB | X19: Lenovo | Y19: ThinkVision | Z19: 17 inch, Square | AA19: VNBNB7L | AB19: 6TCKB03 | AC19: 6TCKB03 | AD19: NKF-19-004-O 06/06 | AE19: NKF-12-007-O-01/02 | AF19: E4-54-E8-7D-FA-92 | AG19: Don't have | AH19: Windows 11 Professional Edition (x64) | AI19: 64 | AJ19: OEM | AK19: VY8N7-FYF8Y-PKRCM-JKFFW-XW3GP | AL19: Microsoft Office Standard 2019 - en-us | AM19: Volume Licensing | AN19: KKY9Y | AO19: Cybereason | AP19: 23.2.243.1 | AQ19: P | AR19: P | AT19: P | AW19: YES | AX19: YES | AY19: wsupawadee@nip.co.th | AZ19: 45841 | BA19: anucha
A20: 16 | B20: 192.168.104.33 | C20: KF-AD-21 | D20: benchaporn.p | E20: NK-NIPPO | F20: Yes | G20: PC | H20: Benchaporn Phoemphun | I20: Ms. Benchaporn Phoemphun | J20: AD - HRM | K20: NK1 | L20: Office Ad | M20: 2019 | N20: =2026-M20 -> 7 | O20: Dell Inc. | P20: OptiPlex 3060 | Q20: Intel(R) Core(TM) i5-8400 CPU @ 2.80GHz | R20: 2.80GHz | S20: 8192 | V20: 500 | W20: Samsung SSD 980 500GB | X20: Lenovo | Y20: ThinkVision | Z20: 17 inch, Square | AA20: VNBB1VV | AB20: 8P25WV2 | AC20: 8P25WV2 | AD20: NKF-19-002-O 07/07 | AE20: NKF-11-067-O-01/02 | AF20: 6C-2B-59-D5-58-D1 | AG20: Don't have | AH20: Windows 11 Professional Edition (x64) | AI20: 64 | AJ20: OEM | AK20: YRHRH-3CNPR-C3HFW-YC78Y-8FG6P | AL20: Microsoft Office Standard 2019 - en-us | AM20: Volume Licensing | AN20: PYWKY | AO20: Cybereason | AP20: 23.2.243.1 | AQ20: P | AR20: P | AT20: P | AW20: YES | AX20: YES | AY20: pbenchaporn@nip.co.th | AZ20: 45841 | BA20: anucha
A21: 17 | B21: 192.168.104.142 | C21: KF-AD-23 | D21: piyachat.p | E21: NK-NIPPO | F21: No | G21: PC | H21: Piyachat Prakongwong | I21: Ms. Piyachat Prakongwong | J21: AD - BOI | K21: NK1 | L21: Office Ad | M21: 2019 | N21: =2026-M21 -> 7 | O21: Dell Inc. | P21: OptiPlex 3060 | Q21: Intel(R) Core(TM) i5-8400 CPU @ 2.80GHz | R21: 2.80GHz | S21: 8192 | V21: 500 | W21: NVMe Samsung SSD 980 | X21: Lenovo | Y21: ThinkVision | Z21: 17 inch, Square | AA21: VNAY5VH | AB21: 8P21WV2 | AC21: 8P21WV2 | AD21: NKF-19-002-O 02/07 | AE21: NKF-10-067-O | AF21: 6C-2B-59-D5-3B-A3 | AG21: Don't have | AH21: Windows 11 Professional Edition (x64) | AI21: 64 | AJ21: OEM | AK21: VHKCT-N3THR-X334Y-FPCWG-FVV22 | AL21: Microsoft Office Standard 2019 - en-us | AM21: Volume Licensing | AN21: V8TVB | AO21: Cybereason | AP21: 23.2.243.1 | AR21: P | AT21: P | AW21: YES | AX21: YES | AY21: ppiyachat@nip.co.th | AZ21: 45841 | BA21: anucha
A22: 18 | B22: 192.168.104.59 | C22: KF-AD-24 | D22: numphung.p | E22: NK-NIPPO | F22: No | G22: PC | H22: Numphung Pothong | I22: Ms. Numphung Pothong | J22: AD - GA | K22: NK1 | L22: Office Ad | M22: 2019 | N22: =2026-M22 -> 7 | O22: Dell Inc. | P22: OptiPlex 3070 | Q22: Intel(R) Core(TM) i5-9500 CPU @ 3.00GHz | R22: 3.00GHz | S22: 8192 | V22: 500 | W22: NVMe Samsung SSD 980 | X22: Lenovo | Y22: ThinkVision | Z22: 17 inch, Square | AA22: VNBTDW8 | AB22: 6T3LB03 | AC22: 6T3LB03 | AD22: NKF-19-006-O 08/24 | AE22: NKF-12-039-O | AF22: E4-54-E8-4D-90-E3 | AG22: Don't have | AH22: Windows 11 Professional Edition (x64) | AI22: 64 | AJ22: OEM | AK22: Sticker spoil | AL22: Microsoft Office Standard 2019 - en-us | AM22: Volume Licensing | AN22: V8TVB | AO22: Cybereason | AP22: 23.2.243.1 | AR22: P | AT22: P | AW22: YES | AX22: YES | AY22: pnumphung@nip.co.th | AZ22: 45841 | BA22: anucha
A23: 19 | B23: 192.168.104.27 | C23: KF-AD-25 | D23: sirikan.j | E23: NK-NIPPO | F23: No | G23: PC | H23: Sirikan Jeerapattanapong | I23: Ms. Sirikan Jeerapattanapong | J23: AD - GA | K23: NK1 | L23: Office Ad | M23: 2019 | N23: =2026-M23 -> 7 | O23: Dell Inc. | P23: OptiPlex 3060 | Q23: Intel(R) Core(TM) i5-8400 CPU @ 2.80GHz | R23: 2.80GHz | S23: 8192 | V23: 500 | W23: Samsung SSD 980 500GB | X23: Lenovo | Y23: ThinkVision | Z23: 17 inch, Square | AA23: VNAXLV6 | AB23: 8P1YVV2 | AC23: 8P1YVV2 | AD23: NKF-19-002-O 03/07 | AE23: NKF-10-073-O | AF23: 6C-2B-59-D5-39-76 | AG23: Don't have | AH23: Windows 11 Professional Edition (x64) | AI23: 64 | AJ23: OEM | AK23: C2WYW-NRQ4B-JDG6X-FW6QB-RC2KC | AL23: Microsoft Office Standard 2019 - en-us | AM23: Volume Licensing | AN23: PYWKY | AO23: Cybereason | AP23: 23.2.243.1 | AR23: P | AT23: P | AW23: YES | AX23: YES | AY23: jsirikan@nip.co.th | AZ23: 45841 | BA23: anucha
A24: 20 | B24: 192.168.104.113 | C24: KF-AD-27 | D24: Security_Guard | E24: NK-NIPPO | F24: No | G24: PC Security_Guard | H24: Numphung Pothong | I24: Ms. Numphung Pothong | J24: AD - GA | K24: NK1 | L24: Guard House | M24: 2019 | N24: =2026-M24 -> 7 | O24: Dell Inc. | P24: OptiPlex 3060 | Q24: Intel(R) Core(TM) i5-8400 CPU @ 2.80GHz | R24: 2.80GHz | S24: 8192 | V24: 500 | W24: NVMe Samsung SSD 980 | X24: Dell | Y24: DELL E170S | Z24: 17 inch, Square | AA24: M875N04Q44PM | AB24: 8P23WV2 | AC24: 8P23WV2 | AD24: NKF-19-002-O 06/07 | AE24: NKF-12-005-O-01/02 | AF24: 6C-2B-59-D5-59-6F | AG24: Don't have | AH24: Windows 11 Professional Edition (x64) | AI24: 64 | AJ24: OEM | AK24: PR7VN-GBQVP-47C9H-DVQ2M-TXXTP | AL24: Microsoft Office Standard 2019 - en-us | AM24: Volume Licensing | AN24: V8TVB | AO24: Cybereason | AP24: 23.2.243.1 | AT24: P | AW24: YES | AX24: YES | AY24: pthapanee@nip.co.th | AZ24: 45841 | BA24: anucha
A25: 21 | B25: 192.168.104.28 | C25: KF-AD-29 | D25: siriphorn.m | E25: NK-NIPPO | F25: No | G25: PC | H25: Siriphorn Maithong | I25: Ms. Siriphorn Maithong | J25: AD - HRD | K25: NK1 | L25: Office Ad | M25: 2019 | N25: =2026-M25 -> 7 | O25: Dell Inc. | P25: OptiPlex 3060 | Q25: Intel(R) Core(TM) i5-8400 CPU @ 2.80GHz | R25: 2.80GHz | S25: 8192 | V25: 500 | W25: NVMe Samsung SSD 980 | X25: Lenovo | Y25: ThinkVision | Z25: 17 inch, Square | AA25: VNBRYDB | AB25: 8P2XVV2 | AC25: 8P2XVV2 | AD25: NKF-19-002-O 04/07 | AE25: NKF-12-044-O-01/02 | AF25: 6C-2B-59-D5-56-54 | AG25: Don't have | AH25: Windows 11 Professional Edition (x64) | AI25: 64 | AJ25: OEM | AK25: X89GH-TNDPV-K83H2-9JQGX-JXCKC | AL25: Microsoft Office Standard 2019 - en-us | AM25: Volume Licensing | AN25: V8TVB | AO25: Cybereason | AP25: 23.2.243.1 | AQ25: P | AR25: P | AT25: P | AW25: YES | AX25: YES | AY25: msiriphorn@nip.co.th | AZ25: 45841 | BA25: anucha
A26: 22 | B26: 192.168.104.215 | C26: KF-AD-31 | D26: amnat.k2 | E26: NK-NIPPO | F26: No | G26: PC | H26: Amnat Kunwandee | I26: Mr. Amnat Kunwandee | J26: AD - IT | K26: NK1 | L26: Office Ad | M26: 2019 | N26: =2026-M26 -> 7 | O26: Dell Inc. | P26: OptiPlex 3070 | Q26: Intel(R) Core(TM) i5-9500 CPU @ 3.00GHz | R26: 3.00GHz | S26: 8192 | V26: 500 | W26: Samsung SSD 980 500GB | X26: Lenovo | Y26: ThinkVision | Z26: 17 inch, Square | AA26: VNAXLTR, VNBAW77 | AB26: 6VJKB03 | AC26: 6VJKB03 | AD26: NKF-19-006-O 19/24 | AE26: NKF-10-061-O, KF6-11-031-O-01/02 | AF26: E4-54-E8-7D-FB-0E | AG26: Don't have | AH26: Windows 11 Professional Edition (x64) | AI26: 64 | AJ26: OEM | AK26: FNRJ4-6B32F-2XX94-TJMYF-BY49C | AL26: Microsoft Office Standard 2019 - en-us | AM26: Volume Licensing | AN26: KKY9Y | AO26: Cybereason | AP26: 23.2.243.1 | AR26: P | AT26: P | AU26: P | AW26: YES | AX26: YES | AY26: kamnat@nip.co.th | AZ26: 45841 | BA26: anucha
A27: 23 | B27: 192.168.104.104 | C27: KF-AD-32 | D27: bigbell.j | E27: NK-NIPPO | F27: No | G27: PC | H27: Bigbell Jaichobsunthia | I27: Ms. Bigbell Jaichobsunthia | J27: AD - IT | K27: NK1 | L27: Office Ad | M27: 2019 | N27: =2026-M27 -> 7 | O27: Dell Inc. | P27: OptiPlex 3070 | Q27: Intel(R) Core(TM) i5-9500 CPU @ 3.00GHz | R27: 3.00GHz | S27: 8192 | V27: 500 | W27: NVMe Samsung SSD 980 | X27: Dell | Y27: E170SC | Z27: 17 inch, Square | AA27: CN-0FHOXK-74261-238-0JPL | AB27: 6VVRB03 | AC27: 6VVRB03 | AD27: NKF-19-006-O 04/24 | AE27: KF5-09-010-O-02/03 | AF27: E4-54-E8-7D-7D-47 | AG27: Don't have | AH27: Windows 11 Professional Edition (x64) | AI27: 64 | AJ27: OEM | AK27: HGT2J-NRFDK-7C2XF-4QG3P-8XCKC | AL27: Microsoft Office Standard 2019 - en-us | AM27: Volume Licensing | AN27: V8TVB | AO27: Cybereason | AP27: 23.2.243.1 | AR27: P | AT27: P | AU27: P | AW27: YES | AX27: YES | AY27: jbigbell@nip.co.th | AZ27: 45841 | BA27: anucha
A28: 24 | B28: 192.168.104.117 | C28: KF-AD-33 | D28: anucha.l | E28: NK-NIPPO | F28: No | G28: PC | H28: Anucha Loket | I28: Mr. Anucha Loket | J28: AD - IT | K28: NK1 | L28: Office Ad | M28: 2019 | N28: =2026-M28 -> 7 | O28: Dell Inc. | P28: OptiPlex 3070 | Q28: Intel(R) Core(TM) i5-9500 CPU @ 3.00GHz | R28: 3.00GHz | S28: 8192 | V28: 500 | W28: NVMe Samsung SSD 980 | X28: HP,ACER | Y28: HP Compaq LA2306x, v173 | Z28: 23 inch-Wide,17 inch, Square | AA28: 3CQ216C8VG, MMLBYSS004235098044225 | AB28: 6V4SB03 | AC28: 6V4SB03 | AD28: NKF-19-006-O 05/24 | AE28: KF5-12-001-O, KF5-12-006-O | AF28: E4-54-E8-7D-FB-E0 | AG28: Don't have | AH28: Windows 11 Professional Edition (x64) | AI28: 64 | AJ28: OEM | AK28: HHHNT-WPK8T-FY8MC-9JT6T-H8RC2 | AL28: Microsoft Office Standard 2019 - en-us | AM28: Volume Licensing | AN28: V8TVB | AO28: Cybereason | AP28: 23.2.243.1 | AR28: P | AT28: P | AU28: P | AW28: YES | AX28: YES | AY28: lanucha@nip.co.th | AZ28: 45841 | BA28: anucha
A29: 25 | B29: 192.168.104.44 | C29: KF-AD-34 | D29: supichaya.jo | E29: NK-NIPPO | F29: No | G29: PC | H29: Supichaya Jornkokgroad | I29: Ms. Supichaya Jornkokgroad | J29: AD - AC | K29: NK1 | L29: Office Ad | M29: 2019 | N29: =2026-M29 -> 7 | O29: Dell Inc. | P29: OptiPlex 3070 | Q29: Intel(R) Core(TM) i5-9500 CPU @ 3.00GHz | R29: 3.00GHz | S29: 8192 | T29: 1024 | U29: ST1000DM010-2EP102 | V29: 500 | W29: Samsung SSD 980 500GB | X29: Lenovo | Y29: ThinkVision | Z29: 17 inch, Square | AA29: VNAXLVW | AB29: 6V9SB03 | AC29: 6V9SB03 | AD29: NKF-19-006-O 09/24 | AE29: NKF-10-069-O | AF29: E4-54-E8-7D-FB-0C | AG29: Don't have | AH29: Windows 11 Professional Edition (x64) | AI29: 64 | AJ29: OEM | AK29: XC2GN-84RPX-4VFCY-967Y4-R3KTP | AL29: Microsoft Office Standard 2019 - en-us | AM29: Volume Licensing | AN29: V8TVB | AO29: Cybereason | AP29: 23.2.243.1 | AR29: P | AT29: P | AU29: P | AW29: YES | AX29: YES | AY29: jsupichaya@nip.co.th | AZ29: 45841 | BA29: anucha
A30: 26 | B30: 192.168.104.39 | C30: KF-AD-35 | D30: rattanaphon.b | E30: NK-NIPPO | F30: No | G30: PC | H30: Rattanaphon Boonroj | I30: Ms. Rattanaphon Boonroj | J30: AD - AC | K30: NK1 | L30: Office Ad | M30: 2019 | N30: =2026-M30 -> 7 | O30: Dell Inc. | P30: OptiPlex 3070 | Q30: Intel(R) Core(TM) i5-9500 CPU @ 3.00GHz | R30: 3.00GHz | S30: 8192 | T30: 1024 | U30: Intel Optane+932GBHDD | X30: Lenovo | Y30: ThinkVision | Z30: 17 inch, Square | AA30: VNAXLTV | AB30: 6VFKB03 | AC30: 6VFKB03 | AD30: NKF-19-004-O 05/06 | AE30: NKF-10-074-O | AF30: E4-54-E8-7D-F9-C4 | AG30: Don't have | AH30: Windows 11 Professional Edition (x64) | AI30: 64 | AJ30: OEM | AK30: PH9NM-MTQJK-P8CCV-PVR6C-GQ722 | AL30: Microsoft Office Standard 2019 - en-us | AM30: Volume Licensing | AN30: KKY9Y | AO30: Cybereason | AP30: 23.2.243.1 | AR30: P | AT30: P | AW30: YES | AX30: YES | AY30: brattanaphon@nip.co.th | AZ30: 45841 | BA30: anucha
A31: 27 | B31: 192.168.104.41 | C31: KF-AD-36 | D31: warin.b | E31: NK-NIPPO | F31: No | G31: PC | H31: Warin Bunchanthuek | I31: Ms. Warin Bunchanthuek | J31: AD - AC | K31: NK1 | L31: Office Ad | M31: 2019 | N31: =2026-M31 -> 7 | O31: Dell Inc. | P31: OptiPlex 3070 | Q31: Intel(R) Core(TM) i5-9500 CPU @ 3.00GHz | R31: 3.00GHz | S31: 8192 | T31: 1024 | U31: Intel Optane+932GBHDD | X31: Lenovo | Y31: ThinkVision | Z31: 17 inch, Square | AA31: VNBNCP2 | AB31: 6W0KB03 | AC31: 6W0KB03 | AD31: NKF-19-004-O 03/06 | AE31: NKF-12-022-O-01/02 | AF31: E4-54-E8-7D-7A-51 | AG31: Don't have | AH31: Windows 11 Professional Edition (x64) | AI31: 64 | AJ31: OEM | AK31: NKHTP-RMJF7-W37GM-C2XDR-FC2KC | AL31: Microsoft Office Standard 2019 - en-us | AM31: Volume Licensing | AN31: KKY9Y | AO31: Cybereason | AP31: 23.2.243.1 | AR31: P | AT31: P | AW31: YES | AX31: YES | AY31: bwarin@nip.co.th | AZ31: 45841 | BA31: anucha
A32: 28 | B32: 192.168.104.42 | C32: KF-AD-37 | D32: sudaluk.b | E32: NK-NIPPO | F32: No | G32: PC | H32: Sudaluk Boonkaree | I32: Ms. Sudaluk Boonkaree | J32: AD - AC | K32: NK1 | L32: Office Ad | M32: 2019 | N32: =2026-M32 -> 7 | O32: Dell Inc. | P32: OptiPlex 3070 | Q32: Intel(R) Core(TM) i5-9500 CPU @ 3.00GHz | R32: 3.00GHz | S32: 8192 | T32: 1024 | U32: Intel Optane+932GBHDD | X32: Lenovo | Y32: ThinkVision | Z32: 17 inch, Square | AA32: VNAXLW9 | AB32: 6V3RB03 | AC32: 6V3RB03 | AD32: NKF-19-004-O 01/06 | AE32: NKF-10-070-O | AF32: E4-54-E8-7E-03-F6 | AG32: Don't have | AH32: Windows 11 Professional Edition (x64) | AI32: 64 | AJ32: OEM | AK32: JRMP4-WNHX4-YG8V8-7J7HM-8FG6P | AL32: Microsoft Office Standard 2019 - en-us | AM32: Volume Licensing | AN32: KKY9Y | AO32: Cybereason | AP32: 23.2.243.1 | AR32: P | AT32: P | AW32: YES | AX32: YES | AY32: bsudaluk@nip.co.th | AZ32: 46073 | BA32: Bancha
A33: 29 | B33: 192.168.104.116 | C33: KF-AD-38 | D33: chonthicha.p | E33: NK-NIPPO | F33: Yes | G33: PC | H33: Chonthicha Phaso | I33: Ms. Chonthicha Phaso | J33: AD - AC | K33: NK1 | L33: Office Ad | M33: 2019 | N33: =2026-M33 -> 7 | O33: Dell Inc. | P33: OptiPlex 3070 | Q33: Intel(R) Core(TM) i5-9500 CPU @ 3.00GHz | R33: 3.00GHz | S33: 8192 | T33: 1024 | U33: Intel Optane+932GBHDD | X33: Dell | Y33: E170SC | Z33: 17 inch, Square | AA33: CN-0M875N-64180-07T-1T1C | AB33: 6T6NB03 | AC33: 6T6NB03 | AD33: NKF-19-004-O 04/06 | AE33: KF4-10-028-O-01/02 | AF33: E4-54-E8-7D-FD-79 | AG33: Don't have | AH33: Windows 11 Professional Edition (x64) | AI33: 64 | AJ33: OEM | AK33: 7M3N7-83HMW-7MV4H-M6DMP-W2QGP | AL33: Microsoft Office Standard 2019 - en-us | AM33: Volume Licensing | AN33: KKY9Y | AO33: Cybereason | AP33: 23.2.243.1 | AR33: P | AT33: P | AW33: YES | AX33: YES | AY33: - | AZ33: 45841 | BA33: anucha
A34: 30 | B34: 192.168.104.132 | C34: KF-AD-40 | D34: weerawan.m | E34: NK-NIPPO | F34: No | G34: PC | H34: Weerawan Meekaew | I34: Ms. Weerawan Meekaew | J34: AD - AC | K34: NK1 | L34: Office Ad | M34: 2019 | N34: =2026-M34 -> 7 | O34: Dell Inc. | P34: OptiPlex 3070 | Q34: Intel(R) Core(TM) i5-9500 CPU @ 3.00GHz | R34: 3.00GHz | S34: 8192 | T34: 1024 | U34: ST1000DM010-2EP102 | V34: 500 | W34: Samsung SSD 980 500GB | X34: Dell | Y34: E170SC | Z34: 17 inch, Square | AA34: CN-0M875N-64180-07T-24FC | AB34: 6VGLB03 | AC34: 6VGLB03 | AD34: NKF-19-004-O 02/06 | AE34: NKF-10-041-O 01/02 | AF34: E4-54-E8-7E-05-17 | AG34: Don't have | AH34: Windows 11 Professional Edition (x64) | AI34: 64 | AJ34: OEM | AK34: GQNY9-JGHVJ-KT3VK-Y4JJ3-7T9TP | AL34: Microsoft Office Standard 2019 - en-us | AM34: Volume Licensing | AN34: KKY9Y | AO34: Cybereason | AP34: 23.2.243.1 | AR34: P | AT34: P | AW34: YES | AX34: YES | AY34: mweerawan@nip.co.th | AZ34: 45841 | BA34: anucha
A35: 31 | B35: 192.168.104.103 | C35: KF-AD-42 | D35: thanphitcha.a | E35: NK-NIPPO | F35: Yes | G35: PC | H35: Thanphitcha Akkara | I35: Ms. Thanphitcha Akkara | J35: AD - AC | K35: NK1 | L35: Office Ad | M35: 2019 | N35: =2026-M35 -> 7 | O35: Dell Inc. | P35: OptiPlex 3070 | Q35: Intel(R) Core(TM) i5-9500 CPU @ 3.00GHz | R35: 3.00GHz | S35: 8192 | V35: 500 | W35: NVMe Samsung SSD 980 | X35: Lenovo | Y35: L1711p | Z35: 17 inch, Square | AA35: VNAXLTT | AB35: 6VTJB03 | AC35: 6VTJB03 | AD35: NKF-19-006-O 23/24 | AE35: D-20-09-001 | AF35: E4-54-E8-7E-03-FC | AG35: Don't have | AH35: Windows 11 Professional Edition (x64) | AI35: 64 | AJ35: OEM | AK35: YK6RN-PJ4HT-XH8TP-WYFC6-D3WXC | AL35: Microsoft Office Standard 2019 - en-us | AM35: Volume Licensing | AN35: V8TVB | AO35: Cybereason | AP35: 23.2.243.1 | AR35: P | AT35: P | AW35: YES | AX35: YES | AY35: athanphitcha@nip.co.th | AZ35: 45841 | BA35: surachet
A36: 32 | B36: #N/A | C36: KF-AD-43 | D36: kf-ad-43 | E36: No Join Domain | F36: No | G36: PC Sound NK1 | H36: AD-IT (Sound NK1) | I36: Mr. Amnat Kunwandee | J36: AD - IT | K36: NK1 | L36: Server Room | M36: 2019 | N36: =2026-M36 -> 7 | O36: Dell Inc. | P36: OptiPlex 3070 | Q36: Intel(R) Core(TM) i5-9500 CPU @ 3.00GHz | R36: 3.00GHz | S36: 8192 | T36: 1024 | X36: Lenovo | Y36: 1708FPT | Z36: 17 inch, Square | AA36: CN-0PM061-71618-773-AMFJ | AB36: 6T0PB03 | AC36: 6T0PB03 | AD36: NKF-19-006-O 12/24 | AE36: KF1-07-009-O 01/02 | AF36: E4-54-E8-7D-FB-8B | AG36: Don't have | AH36: W. 11 Pro | AI36: 64 | AJ36: OEM | AK36: NV23R-8BY9F-DPXBR-PTTD8-6MT6P | AL36: #N/A | AM36: #N/A | AN36: KKY9Y | AO36: Windows Defender | AP36: - | AV36: 5S song | AW36: NO | AX36: NO | AY36: - | AZ36: 45841 | BA36: anucha | BB36: Offline
A37: 33 | B37: 192.168.200.177 | C37: KF-AD-44 | D37: PC | E37: NK-NIPPO | F37: No | G37: PC Sound NK2 | H37: AD-IT (Sound NK1) | I37: Mr. Amnat Kunwandee | J37: AD - IT | K37: NK2 | L37: Server Room | M37: 2019 | N37: =2026-M37 -> 7 | O37: Dell Inc. | P37: OptiPlex 3060 | Q37: Intel(R) Core(TM) i5-8400 CPU @ 2.80GHz | R37: 2.80GHz | S37: 8192 | V37: 240 | W37: KINGSTON SA400S37240G | X37: Dell | Y37: E170SC | Z37: 17 inch, Square | AA37: CN-0M875N-64180-01F-02MM | AB37: 8P20WV2 | AC37: 8P20WV2 | AD37: NKF-19-002-O 5/7 | AE37: NKF-10-002-O 01/02 | AF37: 6C-2B-59-D5-39-DB | AG37: Don't have | AH37: Windows 11 Professional Edition (x64) | AI37: 64 | AJ37: OEM | AK37: KJNCV-7T6VP-7VFJG-323B7-CYT6P | AL37: Microsoft Office Standard 2019 - en-us | AM37: Volume Licensing | AN37: V8TVB | AO37: Cybereason | AP37: 23.2.243.1 | AT37: P | AU37: P | AW37: YES | AX37: NO | AY37: - | AZ37: 45841 | BA37: anucha
A38: 34 | B38: 192.168.104.246 | C38: KF-AD-51 | D38: weeraya.t | E38: NK-NIPPO | F38: No | G38: PC | H38: Weeraya Thongking | I38: Ms. Weeraya Thongking | J38: AD - IT | K38: NK1 | L38: Office Ad | M38: 2019 | N38: =2026-M38 -> 7 | O38: Dell Inc. | P38: OptiPlex 3070 | Q38: Intel(R) Core(TM) i5-9500 CPU @ 3.00GHz | R38: 3.00GHz | S38: 16384 | V38: 500 | W38: NVMe Samsung SSD 980 | X38: Lenovo,Dell | Y38: ThinkVision,E1715S | Z38: 17 inch, Square | AA38: VNB75RT,CN-06FDC0-TV100-328-00PU-A17 | AB38: 6VXKB03 | AC38: 6VXKB03 | AD38: NKF-19-006-O 11/24 | AE38: NKF-11-036-O-01/02,NKF-23-009-O 02/02 | AF38: E4-54-E8-7D-7D-40 | AG38: Don't have | AH38: Windows 11 Professional Edition (x64) | AI38: 64 | AJ38: OEM | AK38: K6MYV-HDN6V-YBR4T-VG448-4VV22 | AL38: Microsoft Office Standard 2019 - en-us | AM38: Volume Licensing | AN38: MDYDR | AO38: Cybereason | AP38: 23.2.243.1 | AR38: P | AU38: P | AW38: YES | AX38: YES | AY38: - | AZ38: 45841 | BA38: anucha
A39: 35 | B39: 10.10.110.18 | C39: KF-AD-52 | D39: - | E39: NK-NIPPO | F39: Yes | G39: NB | H39: - | I39: - | J39: AD | K39: NK1 | L39: Office Ad | M39: 2023 | N39: =2026-M39 -> 3 | O39: Dell Inc. | P39: Latitude 7330 | Q39: 12th Gen Intel(R) Core(TM) i5-1245U | R39: 1.60 GHz | S39: 16384 | V39: 512 | W39: NVMe CL4-3D512-Q11 NVMe SSSTC 512GB | X39: Don't have | Y39: Don't have | Z39: Don't have | AA39: Don't have | AB39: BTL71T3 | AC39: BTL71T3 | AD39: ยังไม่ติดสติกเกอร์ | AE39: Don't have | AF39: 00-09-0F-FE-00-01 | AG39: F4-CE-23-B6-3D-BB | AH39: Windows 11 Professional Edition (x64) | AI39: 64 | AJ39: OEM | AK39: 33QXX-NCCGF-TJ63K-6282C-BTDW6 | AL39: Microsoft Office Home and Business 2021 - en-us | AM39: Full Package Products | AN39: X2HMD | AO39: Cybereason | AP39: 23.2.243.1 | AT39: P | AU39: P | AV39: Cisco meeting,ForitClicent VPN | AW39: YES | AX39: YES | AY39: ynakanishi@nip.co.jp | AZ39: 45841 | BA39: anucha
A40: 36 | B40: 192.168.3.2 | C40: KF-AD-56 | D40: kf-ad-56 | E40: NK-NIPPO | F40: No | G40: PC | H40: AD-IT | I40: Mr. Amnat Kunwandee | J40: AD-IT | K40: NK2 | L40: Server Room | M40: 2023 | N40: =2026-M40 -> 3 | O40: Dell Inc. | P40: OptiPlex SFF 7010 | Q40: 13th Gen Intel(R) Core(TM) i5-13500 | R40: 2.5 GHz | S40: 32768 | T40: 1024 | U40: WDC WD10EZEX-75WN4A1 | V40: 238 | W40: NVMe PM9B1 NVMe Samsung 256GB | X40: Dell | Y40: E1715S | Z40: 17 inch, Square | AA40: CN-06FDC0-TV100-37B-0KGU-A17 | AB40: 78ZMLY3 | AC40: 78ZMLY3 | AD40: ซื้อ 30 Oct 23 | AE40: ซื้อ 30 Oct 23 | AF40: CC-96-E5-2C-8F-FB | AG40: B0-DC-EF-9B-89-DA | AH40: Windows 11 Professional Edition (x64) | AI40: 64 | AJ40: OEM | AK40: NQ8CK-7MQ94-FMQ27-6D9WW-YP22T | AL40: Microsoft Office Home and Business 2021 - en-us | AM40: Full Package Products | AN40: F662Z | AO40: Cybereason | AP40: 23.2.243.1 | AU40: P | AW40: YES | AX40: NO | AY40: - | AZ40: 45841 | BA40: anucha
A41: 37 | B41: 192.168.123.79 | C41: KF-AD-57 | D41: kf-ad-57 | E41: NK-NIPPO | F41: Yes | G41: NB | H41: AD-IT (Support MRP) | I41: #N/A | J41: AD-IT | K41: NK1 | L41: Office Ad | M41: 2024 | N41: =2026-M41 -> 2 | O41: Dell Inc. | P41: Latitude 3540 | Q41: 13th Gen Intel(R) Core(TM) i5-1335U | R41: 4.6GHz | S41: 16384 | V41: 500 | W41: NVMe PM9B1 NVMe Samsung 512GB | AB41: D8Q2PX3 | AC41: D8Q2PX3 | AF41: 4C-D7-17-7C-C9-04 | AG41: D4-E9-8A-B0-3F-65 | AH41: Windows 11 Professional Edition (x64) | AI41: 64 | AJ41: OEM | AK41: N29DH-DMM26-KV92K-996CM-X4TPT | AL41: Microsoft Office Home and Business 2021 - en-us | AM41: Full Package Products | AN41: WVHRJ-XPXDR-FMFWD-DC9Q3-GVXYZ | AO41: Cybereason | AP41: 23.2.243.1 | AR41: P | AW41: YES | AX41: NO | AY41: - | AZ41: 45841 | BA41: anucha
...

Sheet Data
A1: Computer Name
A2: KF-AD-01
A3: KF-AD-02
A4: KF-AD-03
A5: KF-AD-04
A6: KF-AD-05
A7: KF-AD-08
A8: KF-AD-09
A9: KF-AD-10
A10: KF-AD-11
A11: KF-AD-12
A12: KF-AD-13
... A312: VEEAMBACKUP

Sheet 294
A1: KF-SL-10
A2: KF-SL-09
A3: KF-SL-08
A4: KF-SL-07
A5: KF-SL-06
A6: KF-SL-05
A7: KF-SL-04
A8: KF-SL-03
A9: KF-SL-02
A10: KF-SL-01
A11: KF-QA-61
A12: KF-QA-60
... A294: KF-AD-01

Sheet Sheet1
A1: KF-AD-01 | B1: =VLOOKUP(A1,'Device List'!C5:C313,1,FALSE) -> KF-AD-01
A2: KF-AD-02 | B2: =VLOOKUP(A2,'Device List'!C6:C314,1,FALSE) -> KF-AD-02
A3: KF-AD-03 | B3: =VLOOKUP(A3,'Device List'!C7:C314,1,FALSE) -> KF-AD-03
A4: KF-AD-04 | B4: =VLOOKUP(A4,'Device List'!C8:C314,1,FALSE) -> KF-AD-04
A5: KF-AD-05 | B5: =VLOOKUP(A5,'Device List'!C9:C314,1,FALSE) -> KF-AD-05
A6: KF-AD-06 | B6: =VLOOKUP(A6,'Device List'!C10:C314,1,FALSE) -> #N/A
A7: KF-AD-07 | B7: =VLOOKUP(A7,'Device List'!C45:C314,1,FALSE) -> #N/A
A8: KF-AD-08 | B8: =VLOOKUP(A8,'Device List'!C10:C314,1,FALSE) -> KF-AD-08
A9: KF-AD-09 | B9: =VLOOKUP(A9,'Device List'!C11:C314,1,FALSE) -> KF-AD-09
A10: KF-AD-10 | B10: =VLOOKUP(A10,'Device List'!C12:C314,1,FALSE) -> KF-AD-10
A11: KF-AD-11 | B11: =VLOOKUP(A11,'Device List'!C13:C314,1,FALSE) -> KF-AD-11
A12: KF-AD-12 | B12: =VLOOKUP(A12,'Device List'!C14:C314,1,FALSE) -> KF-AD-12
A13: KF-AD-13 | B13: =VLOOKUP(A13,'Device List'!C15:C314,1,FALSE) -> KF-AD-13
A14: KF-AD-14 | B14: =VLOOKUP(A14,'Device List'!C16:C314,1,FALSE) -> KF-AD-14
A15: KF-AD-15 | B15: =VLOOKUP(A15,'Device List'!C17:C314,1,FALSE) -> #N/A
A16: KF-AD-16 | B16: =VLOOKUP(A16,'Device List'!C17:C314,1,FALSE) -> #N/A
A17: KF-AD-18 | B17: =VLOOKUP(A17,'Device List'!C17:C314,1,FALSE) -> KF-AD-18
A18: KF-AD-19 | B18: =VLOOKUP(A18,'Device List'!C18:C314,1,FALSE) -> KF-AD-19
A19: KF-AD-20 | B19: =VLOOKUP(A19,'Device List'!C19:C314,1,FALSE) -> KF-AD-20
A20: KF-AD-21 | B20: =VLOOKUP(A20,'Device List'!C20:C314,1,FALSE) -> KF-AD-21
A21: KF-AD-22 | B21: =VLOOKUP(A21,'Device List'!C21:C314,1,FALSE) -> #N/A
A22: KF-AD-23 | B22: =VLOOKUP(A22,'Device List'!C21:C314,1,FALSE) -> KF-AD-23
A23: KF-AD-24 | B23: =VLOOKUP(A23,'Device List'!C22:C314,1,FALSE) -> KF-AD-24
A24: KF-AD-25 | B24: =VLOOKUP(A24,'Device List'!C23:C314,1,FALSE) -> KF-AD-25
A25: KF-AD-26 | B25: =VLOOKUP(A25,'Device List'!C24:C314,1,FALSE) -> #N/A
A26: KF-AD-27 | B26: =VLOOKUP(A26,'Device List'!C24:C314,1,FALSE) -> KF-AD-27
A27: KF-AD-28 | B27: =VLOOKUP(A27,'Device List'!C25:C314,1,FALSE) -> #N/A
A28: KF-AD-29 | B28: =VLOOKUP(A28,'Device List'!C25:C314,1,FALSE) -> KF-AD-29
A29: KF-AD-30 | B29: =VLOOKUP(A29,'Device List'!C26:C314,1,FALSE) -> #N/A
A30: KF-AD-31 | B30: =VLOOKUP(A30,'Device List'!C26:C314,1,FALSE) -> KF-AD-31
A31: KF-AD-32 | B31: =VLOOKUP(A31,'Device List'!C27:C314,1,FALSE) -> KF-AD-32
A32: KF-AD-33 | B32: =VLOOKUP(A32,'Device List'!C28:C314,1,FALSE) -> KF-AD-33
A33: KF-AD-34 | B33: =VLOOKUP(A33,'Device List'!C29:C314,1,FALSE) -> KF-AD-34
A34: KF-AD-35 | B34: =VLOOKUP(A34,'Device List'!C30:C314,1,FALSE) -> KF-AD-35
A35: KF-AD-36 | B35: =VLOOKUP(A35,'Device List'!C31:C314,1,FALSE) -> KF-AD-36
A36: KF-AD-37 | B36: =VLOOKUP(A36,'Device List'!C32:C314,1,FALSE) -> KF-AD-37
A37: KF-AD-38 | B37: =VLOOKUP(A37,'Device List'!C33:C314,1,FALSE) -> KF-AD-38
A38: KF-AD-39 | B38: =VLOOKUP(A38,'Device List'!C34:C314,1,FALSE) -> #N/A
A39: KF-AD-40 | B39: =VLOOKUP(A39,'Device List'!C34:C314,1,FALSE) -> KF-AD-40
A40: KF-AD-41 | B40: =VLOOKUP(A40,'Device List'!C35:C314,1,FALSE) -> #N/A
...

Sheet Device for audit
A2: No | B2: Network Information | G2: Physical Information | N2: System Information
B3: IP Address | C3: Host Name | D3: User Name | E3: Workgroup/ Domain | F3: Use DHCP | G3: Type | H3: PIC | I3: Department | J3: Location | L3: Year of Purchased | M3: Age (Years) | N3: Brand | O3: Model | P3: CPU | Q3: Speed (GHz)
A5: 1 | B5: 192.168.100.188 | C5: KF-AD-01 | D5: nk1vip1 | E5: NK-NIPPO | F5: No | G5: PC | H5: AD-IT | I5: AD | J5: NK1 | K5: Vip1 Room | L5: 2019 | M5: =2024-L5 -> 5 | N5: Dell Inc. | O5: OptiPlex 3070 | P5: Intel(R) Core(TM) i5-9500 CPU @ 3.00GHz | Q5: 3.00GHz
A6: =A5+1 -> 2 | B6: 192.168.100.149 | C6: KF-AD-02 | D6: nk1vip2 | E6: NK-NIPPO | F6: No | G6: PC | H6: AD-IT | I6: AD | J6: NK1 | K6: Vip2 Room | L6: 2019 | M6: =2024-L6 -> 5 | N6: Dell Inc. | O6: OptiPlex 3070 | P6: Intel(R) Core(TM) i5-9500 CPU @ 3.00GHz | Q6: 3.00GHz
A7: =A6+1 -> 3 | B7: 192.168.100.168 | C7: KF-AD-03 | D7: nk1director | E7: NK-NIPPO | F7: Yes | G7: PC | H7: AD-IT | I7: AD | J7: NK1 | K7: Vip3 Room | L7: 2023 | M7: =2024-L7 -> 1 | N7: Dell Inc. | O7: OptiPlex 7000 | P7: 12th Gen Intel(R) Core(TM) i5-12500 | Q7: 3.00GHz
A8: =A7+1 -> 4 | B8: 192.168.100.193 | C8: KF-AD-04 | D8: nk1guest | E8: NK-NIPPO | F8: No | G8: PC | H8: AD-IT | I8: AD | J8: NK1 | K8: Guest Room | L8: 2023 | M8: =2024-L8 -> 1 | N8: Dell Inc. | O8: OptiPlex 7000 | P8: 12th Gen Intel(R) Core(TM) i5-12500 | Q8: 3.00GHz
A9: =A8+1 -> 5 | B9: 192.168.100.127 | C9: KF-AD-05 | D9: nk1conference1 | E9: NK-NIPPO | F9: No | G9: PC | H9: AD-IT | I9: AD | J9: NK1 | K9: Conference Room 1 | L9: 2019 | M9: =2024-L9 -> 5 | N9: Dell Inc. | O9: OptiPlex 3070 | P9: Intel(R) Core(TM) i5-9500 CPU @ 3.00GHz | Q9: 3.00GHz
A10: =A9+1 -> 6 | B10: 192.168.100.165 | C10: KF-AD-06 | D10: nk1vip3 | E10: NK-NIPPO | F10: Yes | G10: PC | H10: AD-IT | I10: AD | J10: NK1 | K10: Director Room | L10: 2018 | M10: =2024-L10 -> 6 | N10: Dell Inc. | O10: OptiPlex 3050 | P10: Intel(R) Core(TM) i5-7500 CPU @ 3.40GHz | Q10: 3.40GHz
A11: =A10+1 -> 7 | B11: 192.168.100.40 | C11: KF-AD-07 | D11: nk1conference2 | E11: NK-NIPPO | F11: No | G11: PC | H11: AD-IT | I11: AD | J11: NK1 | K11: Conference Room 2 | L11: 2018 | M11: =2024-L11 -> 6 | N11: Dell Inc. | O11: OptiPlex 3050 | P11: Intel(R) Core(TM) i5-7500 CPU @ 3.40GHz | Q11: 3.40GHz
A12: =A11+1 -> 8 | B12: 192.168.10.19 | C12: KF-AD-08 | D12: nk1bigsalon | E12: NK-NIPPO | F12: Yes | G12: PC | H12: AD-IT | I12: AD | J12: NK1 | K12: Bigsalon | L12: 2019 | M12: =2024-L12 -> 5 | N12: Dell Inc. | O12: OptiPlex 3070 | P12: Intel(R) Core(TM) i5-9500 CPU @ 3.00GHz | Q12: 3.00GHz
A13: =A12+1 -> 9 | B13: 192.168.100.92 | C13: KF-AD-09 | D13: nk1lecture1 | E13: NK-NIPPO | F13: No | G13: PC | H13: AD-IT | I13: AD | J13: NK1 | K13: Lecture Room 1 | L13: 2019 | M13: =2024-L13 -> 5 | N13: Dell Inc. | O13: OptiPlex 3070 | P13: Intel(R) Core(TM) i5-9500 CPU @ 3.00GHz | Q13: 3.00GHz
A14: =A13+1 -> 10 | B14: 192.168.100.196 | C14: KF-AD-10 | D14: nk1lecture2 | E14: NK-NIPPO | F14: Yes | G14: PC | H14: AD-IT | I14: AD | J14: NK1 | K14: Lecture Room 2 | L14: 2019 | M14: =2024-L14 -> 5 | N14: Dell Inc. | O14: OptiPlex 3070 | P14: Intel(R) Core(TM) i5-9500 CPU @ 3.00GHz | Q14: 3.00GHz
A15: =A14+1 -> 11 | B15: 192.168.100.198 | C15: KF-AD-11 | D15: nk1meeting1 | E15: NK-NIPPO | F15: Yes | G15: PC | H15: AD-IT | I15: AD | J15: NK1 | K15: Meeting Room 1 (Offoce Center) | L15: 2019 | M15: =2024-L15 -> 5 | N15: Dell Inc. | O15: OptiPlex 3070 | P15: Intel(R) Core(TM) i5-7500 CPU @ 3.40GHz | Q15: 3.40GHz
A16: =A15+1 -> 12 | B16: 192.168.20.122 | C16: KF-AD-12 | D16: nk1meeting2 | E16: NK-NIPPO | F16: Yes | G16: PC | H16: AD-IT | I16: AD | J16: NK1 | K16: Meeting Room 2 (Offoce Center) | L16: 2019 | M16: =2024-L16 -> 5 | N16: Dell Inc. | O16: OptiPlex 3070 | P16: Intel(R) Core(TM) i5-9500 CPU @ 3.00GHz | Q16: 3.00GHz
A17: =A16+1 -> 13 | B17: 192.168.200.160 | C17: KF-AD-13 | D17: nk2vip1 | E17: NK-NIPPO | F17: No | G17: PC | H17: AD-IT | I17: AD | J17: NK2 | K17: Vip 1 | L17: 2019 | M17: =2024-L17 -> 5 | N17: Dell Inc. | O17: OptiPlex 3070 | P17: Intel(R) Core(TM) i5-9500 CPU @ 3.00GHz | Q17: 3.00GHz
... A107: =A106+1 -> 103 | B107: 192.168.20.104 | C107: KF-BCC-09 | D107: aongard.s | E107: NK-NIPPO | F107: Yes | G107: PC | H107: Aongard Suekram | I107: BC CENTER | J107: NK1 | K107: Office Center | L107: 2024 | M107: =2024-L107 -> 0 | N107: Dell Inc. | O107: OptiPlex SFF 7010 | P107: 13th Gen Intel(R) Core(TM) i5-13500 | Q107: 2.5GHz
A108: =A107+1 -> 104 | B108: 192.168.1.15 | C108: KFDMD | E108: NK-NIPPO | F108: Yes | G108: NB | I108: AD | J108: NK1 | K108: Office Ad | L108: 2021 | M108: =2024-L108 -> 3 | N108: Dell Inc. | O108: Latitude 5320 | P108: 11th Gen Intel(R) Core(TM) i5-1135G7 @ 2.40GHz | Q108: 2.40GHz
A109: =A108+1 -> 105 | B109: 192.168.100.201 | C109: KF-EC-01 | D109: kriengkrai.t | E109: NK-NIPPO | F109: No | G109: PC | H109: Kriengkrai Thongraiking | I109: EC | J109: NK1 | K109: Office Ec | L109: 2019 | M109: =2024-L109 -> 5 | N109: Dell Inc. | O109: OptiPlex 3070 | P109: Intel(R) Core(TM) i5-9500 CPU @ 3.00GHz | Q109: 3.00GHz
A110: =A109+1 -> 106 | B110: 192.168.100.160 | C110: KF-EC-02 | D110: kanyanat.k | E110: NK-NIPPO | F110: Yes | G110: PC | H110: Kanyanat Kaewkam | I110: EC | J110: NK1 | K110: Office Ec | L110: 2019 | M110: =2024-L110 -> 5 | N110: Dell Inc. | O110: OptiPlex 3070 | P110: Intel(R) Core(TM) i5-9500 CPU @ 3.00GHz | Q110: 3.00GHz
A111: =A110+1 -> 107 | B111: 192.168.100.68 | C111: KF-EC-03 | D111: itsada.t | E111: NK-NIPPO | F111: No | G111: PC | H111: Itsada Thinnakorn | I111: EC | J111: NK1 | K111: Office Ec | L111: 2019 | M111: =2024-L111 -> 5 | N111: Dell Inc. | O111: OptiPlex 3070 | P111: Intel(R) Core(TM) i5-9500 CPU @ 3.00GHz | Q111: 3.00GHz
A112: =A111+1 -> 108 | B112: 192.168.100.203 | C112: KF-EC-05 | D112: wanmongkol.m | E112: NK-NIPPO | F112: No | G112: Work Station | H112: Wanmongkol Mamaroeng | I112: EC | J112: NK1 | K112: Office Ec | L112: 2020 | M112: =2024-L112 -> 4 | N112: Dell Inc. | O112: Precision 3630 Tower | P112: Intel(R) Core(TM) i7-9700 CPU @ 3.00GHz | Q112: 3.00GHz
A113: =A112+1 -> 109 | B113: 192.168.100.163 | C113: KF-EC-06 | D113: rattanaporn.m | E113: NK-NIPPO | F113: No | G113: PC | H113: Rattanaporn Maisungnoen | I113: EC | J113: NK1 | K113: Office Ec | L113: 2019 | M113: =2024-L113 -> 5 | N113: Dell Inc. | O113: OptiPlex 3070 | P113: Intel(R) Core(TM) i5-9500 CPU @ 3.00GHz | Q113: 3.00GHz
A114: =A113+1 -> 110 | B114: 192.168.100.95 | C114: KF-EC-07 | D114: jureeporn.t | E114: NK-NIPPO | F114: No | G114: PC | H114: Jureeporn Tunsungnoen | I114: EC | J114: NK1 | K114: Office Ec | L114: 2018 | M114: =2024-L114 -> 6 | N114: Dell Inc. | O114: OptiPlex 3050 | P114: Intel(R) Core(TM) i5-7500 CPU @ 3.40GHz | Q114: 3.40GHz
A115: =A114+1 -> 111 | B115: 192.168.100.240 | C115: KF-EC-08 | D115: wichai.t | E115: NK-NIPPO | F115: Yes | G115: PC | H115: Wichai Tasoon | I115: EC | J115: NK1 | K115: Office Ec | L115: 2018 | M115: =2024-L115 -> 6 | N115: Dell Inc. | O115: OptiPlex 3050 | P115: Intel(R) Core(TM) i5-7500 CPU @ 3.40GHz | Q115: 3.40GHz
A116: =A115+1 -> 112 | B116: 192.168.100.214 | C116: KF-EC-09 | D116: aungkana.m | E116: NK-NIPPO | F116: No | G116: PC | H116: Aungkana Mastawong | I116: EC | J116: NK1 | K116: Office Ec | L116: 2019 | M116: =2024-L116 -> 5 | N116: Dell Inc. | O116: OptiPlex 3070 | P116: Intel(R) Core(TM) i5-9500 CPU @ 3.00GHz | Q116: 3.00GHz
A117: =A116+1 -> 113 | B117: 192.168.100.125 | C117: KF-EC-10 | D117: pacharin.p | E117: NK-NIPPO | F117: No | G117: PC | H117: Pacharin Pokhachat | I117: EC | J117: NK1 | K117: Office Ec | L117: 2018 | M117: =2024-L117 -> 6 | N117: Dell Inc. | O117: OptiPlex 3050 | P117: Intel(R) Core(TM) i5-7500 CPU @ 3.40GHz | Q117: 3.40GHz
A118: =A117+1 -> 114 | B118: 192.168.100.124 | C118: KF-EC-11 | D118: krungklai.k | E118: NK-NIPPO | F118: No | G118: Work Station | H118: Krungklai Kalamae | I118: EC | J118: NK1 | K118: Office Ec | L118: 2020 | M118: =2024-L118 -> 4 | N118: Dell Inc. | O118: Precision 3630 Tower | P118: Intel(R) Core(TM) i7-9700 CPU @ 3.00GHz | Q118: 3.00GHz
A119: =A118+1 -> 115 | B119: 192.168.100.180 | C119: KF-EC-12 | D119: pichit.k | E119: NK-NIPPO | F119: No | G119: Work Station | H119: Pichit Khonok | I119: EC | J119: NK1 | K119: Office Ec | L119: 2020 | M119: =2024-L119 -> 4 | N119: Dell Inc. | O119: Precision 3630 Tower | P119: Intel(R) Core(TM) i7-9700 CPU @ 3.00GHz | Q119: 3.00GHz
A120: =A119+1 -> 116 | B120: 10.10.110.33 | C120: KF-EC-13 | D120: suganuma.y | E120: NK-NIPPO | F120: Yes | G120: NB | H120: Yoshifumi Suganuma | I120: QA CENTER | J120: NK2 | K120: Office Precision | L120: 2022 | M120: =2024-L120 -> 2 | N120: Dell Inc. | O120: Latitude 7320 | P120: 11th Gen Intel(R) Core(TM) i5-1135G7 @ 2.40GHz | Q120: 2.40GHz
... A194: =A193+1 -> 190 | B194: 10.10.110.29 | C194: KF6PD2_35 | D194: kanchana.c | E194: NK-NIPPO | F194: No | G194: PC | H194: Kanchana Chaisri | I194: MEDICAL | J194: NK2 | K194: Barcode Med Room | L194: 2020 | M194: =2024-L194 -> 4 | N194: Dell Inc. | O194: OptiPlex 3070 | P194: Intel(R) Core(TM) i5-9500 CPU @ 3.00GHz | Q194: 3.00GHz
A195: =A194+1 -> 191 | B195: 192.168.123.30 | C195: KF-MRT-02 | E195: NK-NIPPO | F195: Yes | G195: NB | I195: AD | J195: NK1 | K195: Office Center | L195: 2019 | M195: =2024-L195 -> 5 | N195: HP | O195: Laptop 15S-FQ1xxx | P195: Intel(R) Core(TM) i5-1035G1 CPU @ 1.00GHz | Q195: 1.00GHz
A196: =A195+1 -> 192 | B196: 10.10.110.24 | C196: KF-MRT-04 | D196: rujira.a | E196: NK-NIPPO | F196: Yes | G196: NB | H196: Rujira Aiamtod | I196: MARKETING | J196: NK1 | K196: Office Center | L196: 2021 | M196: =2024-L196 -> 3 | N196: Dell Inc. | O196: Latitude 3520 | P196: 11th Gen Intel(R) Core(TM) i5-1135G7 @ 2.40GHz | Q196: 2.40GHz
A197: =A196+1 -> 193 | B197: 10.10.110.16 | C197: KF-MRT-05 | D197: vuthichai.m | E197: NK-NIPPO | F197: Yes | G197: NB | H197: Vuthichai Mukpon | I197: MARKETING | J197: NK1 | K197: Office Center | L197: 2023 | M197: =2024-L197 -> 1 | N197: Dell Inc. | O197: Latitude 7330 | P197: 12th Gen Intel(R) Core(TM) i5-1245U | Q197: 1.60GHz
A198: =A197+1 -> 194 | B198: 10.10.110.19 | C198: KF-MRT-06 | D198: prawichaya.j | E198: NK-NIPPO | F198: Yes | G198: NB | H198: Prawichaya Jantaraweeragul | I198: MARKETING | J198: NK1 | K198: Office Center | L198: 2023 | M198: =2024-L198 -> 1 | N198: Dell Inc. | O198: Latitude 3530 | P198: 12th Gen Intel(R) Core(TM) i7-1255U | Q198: 1.70 GHz
A199: =A198+1 -> 195 | B199: 10.10.110.21 | C199: KF-MRT-07 | D199: kanisorn.k | E199: NK-NIPPO | F199: Yes | G199: NB | H199: Kanisorn Kaewluang | I199: MARKETING | J199: NK1 | K199: Office Center | L199: 2023 | M199: =2024-L199 -> 1 | N199: Dell Inc. | O199: Latitude 3530 | P199: 12th Gen Intel(R) Core(TM) i7-1255U | Q199: 1.70 GHz
A200: =A199+1 -> 196 | B200: 10.10.110.13 | C200: KF-MRT-08 | D200: worapun.s | E200: NK-NIPPO | F200: Yes | G200: NB | H200: Worapun Supatwanich | I200: MARKETING | J200: NK1 | K200: Office Center | L200: 2023 | M200: =2024-L200 -> 1 | N200: Dell Inc. | O200: Latitude 3540 | P200: 13th Gen Intel(R) Core(TM) i5-1335U | Q200: 1.30 GHz
A201: =A200+1 -> 197 | B201: 192.168.123.101 | C201: KF-MRT-09 | E201: NK-NIPPO | F201: Yes | G201: NB | I201: MARKETING | J201: NK1 | K201: Office Center | L201: 2024 | M201: =2024-L201 -> 0 | N201: Dell Inc. | O201: Latitude 3540 | P201: 13th Gen Intel(R) Core(TM) i5-1345U | Q201: 1.30 GHz
A202: =A201+1 -> 198 | B202: 10.10.110.15 | C202: KF-PRE-01 | D202: muranaka.t | E202: NK-NIPPO | F202: Yes | G202: NB | H202: Takayuki Muranaka | I202: PRECISION | J202: NK1 | K202: Office Center | L202: 2022 | M202: =2024-L202 -> 2 | N202: Dell Inc. | O202: Latitude 5320 | P202: 11th Gen Intel(R) Core(TM) i5-1135G7 @ 2.40GHz | Q202: 2.60GHz
A203: =A202+1 -> 199 | B203: 192.168.20.20 | C203: KF-PRE-02 | D203: rungsit.u | E203: NK-NIPPO | F203: No | G203: PC | H203: Rungsit Utsaha | I203: BC CENTER | J203: NK1 | K203: Office Center | L203: 2019 | M203: =2024-L203 -> 5 | N203: Dell Inc. | O203: OptiPlex 3070 | P203: Intel(R) Core(TM) i5-9500 CPU @ 3.00GHz | Q203: 3.00GHz
A204: =A203+1 -> 200 | B204: 192.168.20.56 | C204: KF-PRE-04 | D204: surat.c | E204: NK-NIPPO | F204: No | G204: PC | H204: Surat Chadsoongnorn | I204: PRECISION | J204: NK1 | K204: Office Center | L204: 2019 | M204: =2024-L204 -> 5 | N204: Dell Inc. | O204: OptiPlex 5040 | P204: Intel(R) Core(TM) i5-6500 CPU @ 3.20GHz | Q204: 3.00GHz
...
